<sdf version="1.11">
  <model name="robo_urdf">
    <link name="base_link">
      <inertial>
        <pose>0.013020678200872301 -0.017228411308080501 0.078806772449970502 0 0 0</pose>
        <mass>4.17533781895232</mass>
        <inertia>
          <ixx>0.055682348905823603</ixx>
          <ixy>1.55280027163122e-06</ixy>
          <ixz>-7.0361359585238904e-05</ixz>
          <iyy>0.091489450149320806</iyy>
          <iyz>2.61486872412502e-05</iyz>
          <izz>0.13570599544928499</izz>
        </inertia>
      </inertial>
      <collision name="base_link_collision">
        <pose>0 0 0 0 0 0</pose>
        <geometry>
          <mesh>
            <scale>1 1 1</scale>
            <uri>package://openamrobot_description/meshes/visual/base_link.STL</uri>
          </mesh>
        </geometry>
      </collision>
      <visual name="base_link_visual">
        <pose>0 0 0 0 0 0</pose>
        <geometry>
          <mesh>
            <scale>1 1 1</scale>
            <uri>package://openamrobot_description/meshes/visual/base_link.STL</uri>
          </mesh>
        </geometry>
        <material>
          <diffuse>0.990196109 1 1 1</diffuse>
          <ambient>0.990196109 1 1 1</ambient>
        </material>
      </visual>
    </link>
    <joint name="bl_caster_joint" type="revolute">
      <pose relative_to="base_link">-0.27495000000000003 0.215 -0.0092999999999999992 0 0 0</pose>
      <parent>base_link</parent>
      <child>bl_caster_link</child>
      <axis>
        <xyz>0 0 1</xyz>
        <limit>

          <lower>-inf</lower>
          <upper>inf</upper>
        </limit>
        <dynamics>
          <spring_reference>0</spring_reference>
          <spring_stiffness>0</spring_stiffness>
        </dynamics>
      </axis>
    </joint>
    <link name="bl_caster_link">
      <pose relative_to="bl_caster_joint">0 0 0 0 0 0</pose>
      <inertial>
        <pose>-0.0013775144193810499 1.75682554365286e-06 0.00094358223435686605 0 0 0</pose>
        <mass>0.0219398692551676</mass>
        <inertia>
          <ixx>5.4701322378160996e-06</ixx>
          <ixy>7.4914075874195304e-10</ixy>
          <ixz>-4.69358577988104e-07</ixz>
          <iyy>5.29653308929842e-06</iyy>
          <iyz>9.7174897976201692e-10</iyz>
          <izz>8.0764702140362092e-06</izz>
        </inertia>
      </inertial>
      <collision name="bl_caster_link_collision">
        <pose>0 0 0 0 0 0</pose>
        <geometry>
          <mesh>
            <scale>1 1 1</scale>
            <uri>package://openamrobot_description/meshes/visual/bl_caster_link.STL</uri>
          </mesh>
        </geometry>
      </collision>
      <visual name="bl_caster_link_visual">
        <pose>0 0 0 0 0 0</pose>
        <geometry>
          <mesh>
            <scale>1 1 1</scale>
            <uri>package://openamrobot_description/meshes/visual/bl_caster_link.STL</uri>
          </mesh>
        </geometry>
        <material>
          <diffuse>0.990196109 1 1 1</diffuse>
          <ambient>0.990196109 1 1 1</ambient>
        </material>
      </visual>
    </link>
    <joint name="bl_wheel_joint" type="revolute">
      <pose relative_to="bl_caster_link">-0.014999999999999999 0 -0.027746 0 0 0</pose>
      <parent>bl_caster_link</parent>
      <child>bl_wheel_link</child>
      <axis>
        <xyz>0 1 0</xyz>
        <limit>
          <lower>-inf</lower>
          <upper>inf</upper>
        </limit>
        <dynamics>
          <spring_reference>0</spring_reference>
          <spring_stiffness>0</spring_stiffness>
        </dynamics>
      </axis>
    </joint>
    <link name="bl_wheel_link">
      <pose relative_to="bl_wheel_joint">0 0 0 0 0 0</pose>
      <inertial>
        <pose>-7.0655936157404398e-07 -5.5142527752294303e-07 0.00254642490100057 0 0 0</pose>
        <mass>0.024194919184237499</mass>
        <inertia>
          <ixx>3.2497762699627499e-06</ixx>
          <ixy>-2.2744322679216901e-10</ixy>
          <ixz>6.56685274690658e-12</ixz>
          <iyy>3.6558379539539299e-06</iyy>
          <iyz>-2.0759838342628399e-11</iyz>
          <izz>3.2505957651493201e-06</izz>
        </inertia>
      </inertial>
      <collision name="bl_wheel_link_collision">
        <pose>0 0 0 0 0 0</pose>
        <geometry>
          <mesh>
            <scale>1 1 1</scale>
            <uri>package://openamrobot_description/meshes/visual/bl_wheel_link.STL</uri>
          </mesh>
        </geometry>
      </collision>
      <visual name="bl_wheel_link_visual">
        <pose>0 0 0 0 0 0</pose>
        <geometry>
          <mesh>
            <scale>1 1 1</scale>
            <uri>package://openamrobot_description/meshes/visual/bl_wheel_link.STL</uri>
          </mesh>
        </geometry>
        <material>
          <diffuse>0.990196109 1 1 1</diffuse>
          <ambient>0.990196109 1 1 1</ambient>
        </material>
      </visual>
    </link>
    <joint name="br_caster_joint" type="revolute">
      <pose relative_to="base_link">-0.27495000000000003 -0.215 -0.0092999999999999992 0 0 0</pose>
      <parent>base_link</parent>
      <child>br_caster_link</child>
      <axis>
        <xyz>0 0 1</xyz>
        <limit>

          <lower>-inf</lower>
          <upper>inf</upper>
        </limit>
        <dynamics>
          <spring_reference>0</spring_reference>
          <spring_stiffness>0</spring_stiffness>
        </dynamics>
      </axis>
    </joint>
    <link name="br_caster_link">
      <pose relative_to="br_caster_joint">0 0 0 0 0 0</pose>
      <inertial>
        <pose>-0.001377514419381 1.7568255438194001e-06 0.00094358223435691397 0 0 0</pose>
        <mass>0.0219398692551676</mass>
        <inertia>
          <ixx>5.47013223781607e-06</ixx>
          <ixy>7.4914075876645102e-10</ixy>
          <ixz>-4.6935857798809701e-07</ixz>
          <iyy>5.2965330892983903e-06</iyy>
          <iyz>9.7174897977481009e-10</iyz>
          <izz>8.0764702140362092e-06</izz>
        </inertia>
      </inertial>
      <collision name="br_caster_link_collision">
        <pose>0 0 0 0 0 0</pose>
        <geometry>
          <mesh>
            <scale>1 1 1</scale>
            <uri>package://openamrobot_description/meshes/visual/br_caster_link.STL</uri>
          </mesh>
        </geometry>
      </collision>
      <visual name="br_caster_link_visual">
        <pose>0 0 0 0 0 0</pose>
        <geometry>
          <mesh>
            <scale>1 1 1</scale>
            <uri>package://openamrobot_description/meshes/visual/br_caster_link.STL</uri>
          </mesh>
        </geometry>
        <material>
          <diffuse>0.990196109 1 1 1</diffuse>
          <ambient>0.990196109 1 1 1</ambient>
        </material>
      </visual>
    </link>
    <joint name="br_wheel_joint" type="revolute">
      <pose relative_to="br_caster_link">-0.014999999999999999 0 -0.027746 0 0 0</pose>
      <parent>br_caster_link</parent>
      <child>br_wheel_link</child>
      <axis>
        <xyz>0 1 0</xyz>
        <limit>
          <lower>-inf</lower>
          <upper>inf</upper>
        </limit>
        <dynamics>
          <spring_reference>0</spring_reference>
          <spring_stiffness>0</spring_stiffness>
        </dynamics>
      </axis>
    </joint>
    <link name="br_wheel_link">
      <pose relative_to="br_wheel_joint">0 0 0 0 0 0</pose>
      <inertial>
        <pose>-7.06559360075243e-07 -5.51425279493589e-07 0.0025464249010014 0 0 0</pose>
        <mass>0.024194919184242301</mass>
        <inertia>
          <ixx>3.24977626996335e-06</ixx>
          <ixy>-2.2744322636332399e-10</ixy>
          <ixz>6.5668528118426596e-12</ixz>
          <iyy>3.6558379539547401e-06</iyy>
          <iyz>-2.07598381632197e-11</iyz>
          <izz>3.2505957651505102e-06</izz>
        </inertia>
      </inertial>
      <collision name="br_wheel_link_collision">
        <pose>0 0 0 0 0 0</pose>
        <geometry>
          <mesh>
            <scale>1 1 1</scale>
            <uri>package://openamrobot_description/meshes/visual/br_wheel_link.STL</uri>
          </mesh>
        </geometry>
      </collision>
      <visual name="br_wheel_link_visual">
        <pose>0 0 0 0 0 0</pose>
        <geometry>
          <mesh>
            <scale>1 1 1</scale>
            <uri>package://openamrobot_description/meshes/visual/br_wheel_link.STL</uri>
          </mesh>
        </geometry>
        <material>
          <diffuse>0.990196109 1 1 1</diffuse>
          <ambient>0.990196109 1 1 1</ambient>
        </material>
      </visual>
    </link>
    <joint name="fl_caster_joint" type="revolute">
      <pose relative_to="base_link">0.27505000000000002 0.215 -0.0092999999999999992 0 0 0</pose>
      <parent>base_link</parent>
      <child>fl_caster_link</child>
      <axis>
        <xyz>0 0 1</xyz>
        <limit>

          <lower>-inf</lower>
          <upper>inf</upper>
        </limit>
        <dynamics>
          <spring_reference>0</spring_reference>
          <spring_stiffness>0</spring_stiffness>
        </dynamics>
      </axis>
    </joint>
    <link name="fl_caster_link">
      <pose relative_to="fl_caster_joint">0 0 0 0 0 0</pose>
      <inertial>
        <pose>-0.00137751441938117 1.7568255438749099e-06 0.00094358223435681704 0 0 0</pose>
        <mass>0.021939869255167901</mass>
        <inertia>
          <ixx>5.4701322378161098e-06</ixx>
          <ixy>7.49140758780352e-10</ixy>
          <ixz>-4.6935857798812602e-07</ixz>
          <iyy>5.29653308929842e-06</iyy>
          <iyz>9.7174897982221995e-10</iyz>
          <izz>8.0764702140362092e-06</izz>
        </inertia>
      </inertial>
      <collision name="fl_caster_link_collision">
        <pose>0 0 0 0 0 0</pose>
        <geometry>
          <mesh>
            <scale>1 1 1</scale>
            <uri>package://openamrobot_description/meshes/visual/fl_caster_link.STL</uri>
          </mesh>
        </geometry>
      </collision>
      <visual name="fl_caster_link_visual">
        <pose>0 0 0 0 0 0</pose>
        <geometry>
          <mesh>
            <scale>1 1 1</scale>
            <uri>package://openamrobot_description/meshes/visual/fl_caster_link.STL</uri>
          </mesh>
        </geometry>
        <material>
          <diffuse>0.990196109 1 1 1</diffuse>
          <ambient>0.990196109 1 1 1</ambient>
        </material>
      </visual>
    </link>
    <joint name="fl_wheel_joint" type="revolute">
      <pose relative_to="fl_caster_link">-0.014999999999999999 0 -0.027746 0 0 0</pose>
      <parent>fl_caster_link</parent>
      <child>fl_wheel_link</child>
      <axis>
        <xyz>0 1 0</xyz>
        <limit>
          <lower>-inf</lower>
          <upper>inf</upper>
        </limit>
        <dynamics>
          <spring_reference>0</spring_reference>
          <spring_stiffness>0</spring_stiffness>
        </dynamics>
      </axis>
    </joint>
    <link name="fl_wheel_link">
      <pose relative_to="fl_wheel_joint">0 0 0 0 0 0</pose>
      <inertial>
        <pose>-6.3956906243278798e-07 0.000112518782016985 0.00254643003871692 0 0 0</pose>
        <mass>0.026729164264555499</mass>
        <inertia>
          <ixx>3.7398971674152998e-06</ixx>
          <ixy>-2.27443217252895e-10</ixy>
          <ixz>6.5673969996440897e-12</ixz>
          <iyy>3.6803685469895001e-06</iyy>
          <iyz>-2.0759852367139901e-11</iyz>
          <izz>3.7407166619727202e-06</izz>
        </inertia>
      </inertial>
      <collision name="fl_wheel_link_collision">
        <pose>0 0 0 0 0 0</pose>
        <geometry>
          <mesh>
            <scale>1 1 1</scale>
            <uri>package://openamrobot_description/meshes/visual/fl_wheel_link.STL</uri>
          </mesh>
        </geometry>
      </collision>
      <visual name="fl_wheel_link_visual">
        <pose>0 0 0 0 0 0</pose>
        <geometry>
          <mesh>
            <scale>1 1 1</scale>
            <uri>package://openamrobot_description/meshes/visual/fl_wheel_link.STL</uri>
          </mesh>
        </geometry>
        <material>
          <diffuse>0.990196109 1 1 1</diffuse>
          <ambient>0.990196109 1 1 1</ambient>
        </material>
      </visual>
    </link>
    <joint name="fr_caster_joint" type="revolute">
      <pose relative_to="base_link">0.27505000000000002 -0.215 -0.0092999999999999992 0 0 0</pose>
      <parent>base_link</parent>
      <child>fr_caster_link</child>
      <axis>
        <xyz>0 0 1</xyz>
        <limit>

          <lower>-inf</lower>
          <upper>inf</upper>
        </limit>
        <dynamics>
          <spring_reference>0</spring_reference>
          <spring_stiffness>0</spring_stiffness>
        </dynamics>
      </axis>
    </joint>
    <link name="fr_caster_link">
      <pose relative_to="fr_caster_joint">0 0 0 0 0 0</pose>
      <inertial>
        <pose>-0.001377514419381 1.75682554379164e-06 0.00094358223435699095 0 0 0</pose>
        <mass>0.021939869255167398</mass>
        <inertia>
          <ixx>5.4701322378160403e-06</ixx>
          <ixy>7.4914075876170001e-10</ixy>
          <ixz>-4.6935857798809299e-07</ixz>
          <iyy>5.2965330892983598e-06</iyy>
          <iyz>9.7174897980342599e-10</iyz>
          <izz>8.0764702140361499e-06</izz>
        </inertia>
      </inertial>
      <collision name="fr_caster_link_collision">
        <pose>0 0 0 0 0 0</pose>
        <geometry>
          <mesh>
            <scale>1 1 1</scale>
            <uri>package://openamrobot_description/meshes/visual/fr_caster_link.STL</uri>
          </mesh>
        </geometry>
      </collision>
      <visual name="fr_caster_link_visual">
        <pose>0 0 0 0 0 0</pose>
        <geometry>
          <mesh>
            <scale>1 1 1</scale>
            <uri>package://openamrobot_description/meshes/visual/fr_caster_link.STL</uri>
          </mesh>
        </geometry>
        <material>
          <diffuse>0.990196109 1 1 1</diffuse>
          <ambient>0.990196109 1 1 1</ambient>
        </material>
      </visual>
    </link>
    <joint name="fr_wheel_joint" type="revolute">
      <pose relative_to="fr_caster_link">-0.014999999999999999 0 -0.027746 0 0 0</pose>
      <parent>fr_caster_link</parent>
      <child>fr_wheel_link</child>
      <axis>
        <xyz>0 1 0</xyz>
        <limit>
          <lower>-inf</lower>
          <upper>inf</upper>
        </limit>
        <dynamics>
          <spring_reference>0</spring_reference>
          <spring_stiffness>0</spring_stiffness>
        </dynamics>
      </axis>
    </joint>
    <link name="fr_wheel_link">
      <pose relative_to="fr_wheel_joint">0 0 0 0 0 0</pose>
      <inertial>
        <pose>-7.0655935713315198e-07 -5.5142527616292004e-07 0.0025464249010003102 0 0 0</pose>
        <mass>0.024194919184234501</mass>
        <inertia>
          <ixx>3.2497762699624302e-06</ixx>
          <ixy>-2.2744322564586801e-10</ixy>
          <ixz>6.5668525167281998e-12</ixz>
          <iyy>3.6558379539534302e-06</iyy>
          <iyz>-2.0759838441347901e-11</iyz>
          <izz>3.2505957651484599e-06</izz>
        </inertia>
      </inertial>
      <collision name="fr_wheel_link_collision">
        <pose>0 0 0 0 0 0</pose>
        <geometry>
          <mesh>
            <scale>1 1 1</scale>
            <uri>package://openamrobot_description/meshes/visual/fr_wheel_link.STL</uri>
          </mesh>
        </geometry>
      </collision>
      <visual name="fr_wheel_link_visual">
        <pose>0 0 0 0 0 0</pose>
        <geometry>
          <mesh>
            <scale>1 1 1</scale>
            <uri>package://openamrobot_description/meshes/visual/fr_wheel_link.STL</uri>
          </mesh>
        </geometry>
        <material>
          <diffuse>0.990196109 1 1 1</diffuse>
          <ambient>0.990196109 1 1 1</ambient>
        </material>
      </visual>
    </link>
    <joint name="left_wheel_joint" type="revolute">
      <pose relative_to="base_link">4.7743e-05 0.20374999999999999 0.046532999999999998 0 0 0</pose>
      <parent>base_link</parent>
      <child>left_wheel_link</child>
      <axis>
        <xyz>0 1 0</xyz>
        <limit>
          <lower>-inf</lower>
          <upper>inf</upper>
        </limit>
        <dynamics>
          <spring_reference>0</spring_reference>
          <spring_stiffness>0</spring_stiffness>
        </dynamics>
      </axis>
    </joint>
    <link name="left_wheel_link">
      <pose relative_to="left_wheel_joint">0 0 0 0 0 0</pose>
      <inertial>
        <pose>6.2850299915433297e-07 -0.0039870676124848002 -0.00056979097738427099 0 0 0</pose>
        <mass>1.06112497715273</mass>
        <inertia>
          <ixx>0.0033990048798655699</ixx>
          <ixy>-1.5883885052325502e-08</ixy>
          <ixz>-5.9956027195172104e-08</ixz>
          <iyy>0.0064263496943662898</iyy>
          <iyz>-1.6676463355727101e-07</iyz>
          <izz>0.0033973895137008</izz>
        </inertia>
      </inertial>
      <collision name="left_wheel_link_collision">
        <pose>0 0 0 0 0 0</pose>
        <geometry>
          <mesh>
            <scale>1 1 1</scale>
            <uri>package://openamrobot_description/meshes/visual/left_wheel_link.STL</uri>
          </mesh>
        </geometry>
      </collision>
      <visual name="left_wheel_link_visual">
        <pose>0 0 0 0 0 0</pose>
        <geometry>
          <mesh>
            <scale>1 1 1</scale>
            <uri>package://openamrobot_description/meshes/visual/left_wheel_link.STL</uri>
          </mesh>
        </geometry>
        <material>
          <diffuse>0.990196109 1 1 1</diffuse>
          <ambient>0.990196109 1 1 1</ambient>
        </material>
      </visual>
    </link>
    <joint name="lidar_joint" type="fixed">
      <pose relative_to="base_link">0.35135 -0.0010250999999999999 0.16830000000000001 0 0 0</pose>
      <parent>base_link</parent>
      <child>lidar_link</child>
      <axis>
        <xyz>0 0 1</xyz>
        <limit>
          <lower>-inf</lower>
          <upper>inf</upper>
        </limit>
        <dynamics>
          <spring_reference>0</spring_reference>
          <spring_stiffness>0</spring_stiffness>
        </dynamics>
      </axis>
    </joint>
    <link name="lidar_link">
      <pose relative_to="lidar_joint">0 0 0 0 0 0</pose>
      <inertial>
        <pose>-0.028276907815541999 0.00091902522027920098 -0.0114509307164145 0 0 0</pose>
        <mass>0.16763366422730699</mass>
        <inertia>
          <ixx>5.11992170336187e-05</ixx>
          <ixy>4.4944387649134402e-07</ixy>
          <ixz>1.5052713226636e-07</ixz>
          <iyy>5.9736421631116297e-05</iyy>
          <iyz>5.0250495067312099e-08</iyz>
          <izz>0.00010092486548458301</izz>
        </inertia>
      </inertial>
      <collision name="lidar_link_collision">
        <pose>0 0 0 0 0 0</pose>
        <geometry>
          <mesh>
            <scale>1 1 1</scale>
            <uri>package://openamrobot_description/meshes/visual/lidar_link.STL</uri>
          </mesh>
        </geometry>
      </collision>
      <visual name="lidar_link_visual">
        <pose>0 0 0 0 0 0</pose>
        <geometry>
          <mesh>
            <scale>1 1 1</scale>
            <uri>package://openamrobot_description/meshes/visual/lidar_link.STL</uri>
          </mesh>
        </geometry>
        <material>
          <diffuse>0.990196109 1 1 1</diffuse>
          <ambient>0.990196109 1 1 1</ambient>
        </material>
      </visual>
    </link>
    <joint name="right_wheel_joint" type="revolute">
      <pose relative_to="base_link">4.7657000000000001e-05 -0.20374999999999999 0.046532999999999998 0 0 0</pose>
      <parent>base_link</parent>
      <child>right_wheel_link</child>
      <axis>
        <xyz>0 1 0</xyz>
        <limit>
          <lower>-inf</lower>
          <upper>inf</upper>
        </limit>
        <dynamics>
          <spring_reference>0</spring_reference>
          <spring_stiffness>0</spring_stiffness>
        </dynamics>
      </axis>
    </joint>
    <link name="right_wheel_link">
      <pose relative_to="right_wheel_joint">0 0 0 0 0 0</pose>
      <inertial>
        <pose>-6.2850299915386996e-07 0.0039870676124848002 -0.00056979097738427099 0 0 0</pose>
        <mass>1.06112497715273</mass>
        <inertia>
          <ixx>0.0033990048798655699</ixx>
          <ixy>-1.5883885052322199e-08</ixy>
          <ixz>5.9956027195172302e-08</ixz>
          <iyy>0.0064263496943662898</iyy>
          <iyz>1.6676463355727101e-07</iyz>
          <izz>0.0033973895137008</izz>
        </inertia>
      </inertial>
      <collision name="right_wheel_link_collision">
        <pose>0 0 0 0 0 0</pose>
        <geometry>
          <mesh>
            <scale>1 1 1</scale>
            <uri>package://openamrobot_description/meshes/visual/right_wheel_link.STL</uri>
          </mesh>
        </geometry>
      </collision>
      <visual name="right_wheel_link_visual">
        <pose>0 0 0 0 0 0</pose>
        <geometry>
          <mesh>
            <scale>1 1 1</scale>
            <uri>package://openamrobot_description/meshes/visual/right_wheel_link.STL</uri>
          </mesh>
        </geometry>
        <material>
          <diffuse>0.990196109 1 1 1</diffuse>
          <ambient>0.990196109 1 1 1</ambient>
        </material>
      </visual>
    </link>
    <plugin filename="gz-sim-diff-drive-system" name="gz::sim::systems::DiffDrive">
      <left_joint>left_wheel_joint</left_joint>
      <right_joint>right_wheel_joint</right_joint>
      <wheel_separation>0.4075</wheel_separation>
      <wheel_radius>0.046533</wheel_radius>
      <odom_publish_frequency>50</odom_publish_frequency>
      <topic>/cmd_vel</topic>
      <odom_topic>/odom</odom_topic>
      <tf_topic>/tf</tf_topic>
      <frame_id>odom</frame_id>
      <child_frame_id>base_link</child_frame_id>
    </plugin>
  </model>
</sdf>